2025-04-05 10:20:42,951 : INFO : Start of Prediction
2025-04-05 10:20:42,951 : INFO : run_id:2025-04-05_102042_108572458
2025-04-05 10:20:42,951 : INFO : Start of Preprocessing...
2025-04-05 10:20:42,951 : INFO : Start of feature encoding...
2025-04-05 10:20:42,951 : INFO : End of feature encoding...
2025-04-05 10:20:42,959 : INFO : Start of Droping Columns...
2025-04-05 10:20:42,959 : INFO : End of Droping Columns...
2025-04-05 10:20:42,961 : INFO : Start of finding missing values...
2025-04-05 10:20:42,961 : INFO : End of finding missing values...
2025-04-05 10:20:42,961 : INFO : Start of building final predictset...
2025-04-05 10:20:42,971 : INFO : End of building final predictset...
2025-04-05 10:20:42,971 : INFO : End of Preprocessing...
2025-04-05 10:20:42,971 : INFO : Start of Load Model
2025-04-05 10:20:42,971 : INFO : Model File KMeans loaded
2025-04-05 10:20:42,971 : INFO : End of Load Model
2025-04-05 10:20:42,992 : INFO : clusters loop started
2025-04-05 10:20:42,995 : INFO : Start of finding correct model
2025-04-05 10:20:42,995 : INFO : Exception raised while finding correct model'FileOperation' object has no attribute 'model_name'
2025-04-05 10:20:43,000 : ERROR : Unsuccessful End of Prediction
Traceback (most recent call last):
  File "D:\Major Project\Employee_Retention_ML-main\apps\core\file_operation.py", line 56, in correct_model
    self.model_name=self.model_name.split('.')[0]
                    ^^^^^^^^^^^^^^^
AttributeError: 'FileOperation' object has no attribute 'model_name'. Did you mean: 'folder_name'?

During handling of the above exception, another exception occurred:

Traceback (most recent call last):
  File "D:\Major Project\Employee_Retention_ML-main\apps\prediction\predict_model.py", line 65, in single_predict_from_model
    model_name = self.fileOperation.correct_model(i)
                 ^^^^^^^^^^^^^^^^^^^^^^^^^^^^^^^^^^^
  File "D:\Major Project\Employee_Retention_ML-main\apps\core\file_operation.py", line 61, in correct_model
    raise Exception()
Exception
