2025-03-27 23:46:30,913 : INFO : Start of Prediction
2025-03-27 23:46:30,916 : INFO : run_id:2025-03-27_234630_455801918
2025-03-27 23:46:30,916 : INFO : Start of Data Load, validation and transformation
2025-03-27 23:46:30,916 : INFO : Start of Archiving Old Rejected Files...
2025-03-27 23:46:30,916 : INFO : End of Archiving Old Rejected Files...
2025-03-27 23:46:30,916 : INFO : Start of Archiving Old Validated Files...
2025-03-27 23:46:30,916 : INFO : End of Archiving Old Validated Files...
2025-03-27 23:46:30,916 : INFO : Start of Archiving Old Processed Files...
2025-03-27 23:46:30,916 : INFO : End of Archiving Old Processed Files...
2025-03-27 23:46:30,916 : INFO : Start of Archiving Old Result Files...
2025-03-27 23:46:30,922 : INFO : End of Archiving Old Result Files...
2025-03-27 23:46:30,923 : INFO : Start of Reading values From Schema...
2025-03-27 23:46:30,923 : INFO : End of Reading values From Schema...
2025-03-27 23:46:30,923 : INFO : Start of Validating Column Length...
2025-03-27 23:46:30,923 : ERROR : OSError raised while Validating Column Length
Traceback (most recent call last):
  File "D:\Major Project\Employee_Retention_ML-main\apps\ingestion\load_validate.py", line 41, in validate_column_length
    for file in listdir(self.data_path):
                ^^^^^^^^^^^^^^^^^^^^^^^
NotADirectoryError: [WinError 267] The directory name is invalid: 'data/prediction_data\\batch_2025-03-27_234630_455801918.csv'
2025-03-27 23:46:30,925 : ERROR : Unsuccessful End of Data Load, validation and transformation
Traceback (most recent call last):
  File "D:\Major Project\Employee_Retention_ML-main\apps\ingestion\load_validate.py", line 41, in validate_column_length
    for file in listdir(self.data_path):
                ^^^^^^^^^^^^^^^^^^^^^^^
NotADirectoryError: [WinError 267] The directory name is invalid: 'data/prediction_data\\batch_2025-03-27_234630_455801918.csv'

During handling of the above exception, another exception occurred:

Traceback (most recent call last):
  File "D:\Major Project\Employee_Retention_ML-main\apps\ingestion\load_validate.py", line 210, in validate_predictset
    self.validate_column_length(number_of_columns)
  File "D:\Major Project\Employee_Retention_ML-main\apps\ingestion\load_validate.py", line 52, in validate_column_length
    raise OSError
OSError
2025-03-27 23:46:30,925 : ERROR : Unsuccessful End of Prediction
Traceback (most recent call last):
  File "D:\Major Project\Employee_Retention_ML-main\apps\ingestion\load_validate.py", line 41, in validate_column_length
    for file in listdir(self.data_path):
                ^^^^^^^^^^^^^^^^^^^^^^^
NotADirectoryError: [WinError 267] The directory name is invalid: 'data/prediction_data\\batch_2025-03-27_234630_455801918.csv'

During handling of the above exception, another exception occurred:

Traceback (most recent call last):
  File "D:\Major Project\Employee_Retention_ML-main\apps\ingestion\load_validate.py", line 210, in validate_predictset
    self.validate_column_length(number_of_columns)
  File "D:\Major Project\Employee_Retention_ML-main\apps\ingestion\load_validate.py", line 52, in validate_column_length
    raise OSError
OSError

During handling of the above exception, another exception occurred:

Traceback (most recent call last):
  File "D:\Major Project\Employee_Retention_ML-main\apps\prediction\predict_model.py", line 21, in batch_predict_from_model
    self.loadValidate.validate_predictset()
  File "D:\Major Project\Employee_Retention_ML-main\apps\ingestion\load_validate.py", line 226, in validate_predictset
    raise Exception
Exception
